+ source ../common_lib/fsio_lib.sh
++ source /root/mugen-riscv/libs/locallibs/common_lib.sh
+++ python3 --version
+++ '[' 0 -eq 0 ']'
+++ source /root/mugen-riscv/libs/locallibs/common_lib_python.sh
++ export 'FS_TYPE=ext3 ext4 xfs'
++ FS_TYPE='ext3 ext4 xfs'
++ export LANG=en_US.UTF-8
++ LANG=en_US.UTF-8
++ REMOVE_VG
++ vggroup=
++ [[ '' != '' ]]
+++ grep test_vggroup
+++ df -T
+++ awk '{print $7}'
++ mounted=
++ [[ '' != '' ]]
++ lsblk
++ grep test_vggroup
++ [[ 1 -eq 0 ]]
++ rm -rf '/tmp/point*'
+ main
++ type -t post_test
+ '[' -n function ']'
+ trap post_test EXIT INT HUP TERM
+ grep expect
+ rpm -qa
++ type -t config_params
+ '[' -n '' ']'
++ type -t pre_test
+ '[' -n function ']'
+ pre_test
+ LOG_INFO 'Start to prepare the database config.'
+ message='Start to prepare the database config.'
+ python3 /root/mugen-riscv/libs/locallibs/mugen_log.py --level info --message 'Start to prepare the database config.'
Tue Aug 29 10:14:59 2023 - INFO  - Start to prepare the database config.
++ date +%Y%m%d%H%M%S
+ cur_date=20230829101459
++ CREATE_VG
+++ date +%Y%m%d%H%M%S
++ cur_date=20230829101459
+++ lsblk
+++ grep disk
+++ tail -n 1
+++ awk '{print $1}'
++ free_disk=vda
++ disk_name=/dev/vda
++ pvcreate /dev/vda -f
++ [[ 127 -eq 0 ]]
+++ pvcreate /dev/vda
+++ grep test_vggroup
+++ cut -d '"' -f 4
++ vggroup=
++ printf
printf: usage: printf [-v var] format [arguments]
+ vggroup=
+ lv=test_lv20230829101459
+ lvcreate -n test_lv20230829101459 -L 2G -y
oe_test_FSIO_mount_umount_ext4.sh: line 26: lvcreate: command not found
+ mkfs.ext4 /dev//test_lv20230829101459
mke2fs 1.47.0 (5-Feb-2023)
The file /dev//test_lv20230829101459 does not exist and no size was specified.
+ ext4_mount=/mnt/ext4_mount20230829101459
+ mkdir /mnt/ext4_mount20230829101459
+ LOG_INFO 'Finish to prepare the database config.'
+ message='Finish to prepare the database config.'
+ python3 /root/mugen-riscv/libs/locallibs/mugen_log.py --level info --message 'Finish to prepare the database config.'
Tue Aug 29 10:14:59 2023 - INFO  - Finish to prepare the database config.
++ type -t run_test
+ '[' -n function ']'
+ run_test
+ LOG_INFO 'Start to run test.'
+ message='Start to run test.'
+ python3 /root/mugen-riscv/libs/locallibs/mugen_log.py --level info --message 'Start to run test.'
Tue Aug 29 10:14:59 2023 - INFO  - Start to run test.
+ mount -t ext4 /dev//test_lv20230829101459 /mnt/ext4_mount20230829101459
mount: /mnt/ext4_mount20230829101459: special device /dev//test_lv20230829101459 does not exist.
       dmesg(1) may have more information after failed mount system call.
+ CHECK_RESULT 32 0 0 'mount ext4 failed.'
+ actual_result=32
+ expect_result=0
+ mode=0
+ error_log='mount ext4 failed.'
+ '[' -z 32 ']'
+ '[' 0 -eq 0 ']'
+ test 32x '!=' 0x
+ test -n 'mount ext4 failed.'
+ LOG_ERROR 'mount ext4 failed.'
+ message='mount ext4 failed.'
+ python3 /root/mugen-riscv/libs/locallibs/mugen_log.py --level error --message 'mount ext4 failed.'
Tue Aug 29 10:14:59 2023 - ERROR - mount ext4 failed.
+ (( exec_result++ ))
+ LOG_ERROR 'oe_test_FSIO_mount_umount_ext4.sh line 36'
+ message='oe_test_FSIO_mount_umount_ext4.sh line 36'
+ python3 /root/mugen-riscv/libs/locallibs/mugen_log.py --level error --message 'oe_test_FSIO_mount_umount_ext4.sh line 36'
Tue Aug 29 10:14:59 2023 - ERROR - oe_test_FSIO_mount_umount_ext4.sh line 36
+ return 0
+ df -h
+ grep /mnt/ext4_mount20230829101459
+ CHECK_RESULT 1 0 0 'Check mount infos failed.'
+ actual_result=1
+ expect_result=0
+ mode=0
+ error_log='Check mount infos failed.'
+ '[' -z 1 ']'
+ '[' 0 -eq 0 ']'
+ test 1x '!=' 0x
+ test -n 'Check mount infos failed.'
+ LOG_ERROR 'Check mount infos failed.'
+ message='Check mount infos failed.'
+ python3 /root/mugen-riscv/libs/locallibs/mugen_log.py --level error --message 'Check mount infos failed.'
Tue Aug 29 10:14:59 2023 - ERROR - Check mount infos failed.
+ (( exec_result++ ))
+ LOG_ERROR 'oe_test_FSIO_mount_umount_ext4.sh line 38'
+ message='oe_test_FSIO_mount_umount_ext4.sh line 38'
+ python3 /root/mugen-riscv/libs/locallibs/mugen_log.py --level error --message 'oe_test_FSIO_mount_umount_ext4.sh line 38'
Tue Aug 29 10:14:59 2023 - ERROR - oe_test_FSIO_mount_umount_ext4.sh line 38
+ return 0
+ umount /mnt/ext4_mount20230829101459
umount: /mnt/ext4_mount20230829101459: not mounted.
+ CHECK_RESULT 32 0 0 'umount ext4 failed.'
+ actual_result=32
+ expect_result=0
+ mode=0
+ error_log='umount ext4 failed.'
+ '[' -z 32 ']'
+ '[' 0 -eq 0 ']'
+ test 32x '!=' 0x
+ test -n 'umount ext4 failed.'
+ LOG_ERROR 'umount ext4 failed.'
+ message='umount ext4 failed.'
+ python3 /root/mugen-riscv/libs/locallibs/mugen_log.py --level error --message 'umount ext4 failed.'
Tue Aug 29 10:14:59 2023 - ERROR - umount ext4 failed.
+ (( exec_result++ ))
+ LOG_ERROR 'oe_test_FSIO_mount_umount_ext4.sh line 40'
+ message='oe_test_FSIO_mount_umount_ext4.sh line 40'
+ python3 /root/mugen-riscv/libs/locallibs/mugen_log.py --level error --message 'oe_test_FSIO_mount_umount_ext4.sh line 40'
Tue Aug 29 10:14:59 2023 - ERROR - oe_test_FSIO_mount_umount_ext4.sh line 40
+ return 0
++ blkid
++ grep /dev/mapper/-test_lv20230829101459
++ awk '{print $2}'
++ cut -d '"' -f 2
+ uuid=
+ mount UUID= /mnt/ext4_mount20230829101459
mount: /mnt/ext4_mount20230829101459: special device UUID= does not exist.
       dmesg(1) may have more information after failed mount system call.
+ df -h
+ grep /mnt/ext4_mount20230829101459
+ CHECK_RESULT 1 0 0 'Check mount infos failed.'
+ actual_result=1
+ expect_result=0
+ mode=0
+ error_log='Check mount infos failed.'
+ '[' -z 1 ']'
+ '[' 0 -eq 0 ']'
+ test 1x '!=' 0x
+ test -n 'Check mount infos failed.'
+ LOG_ERROR 'Check mount infos failed.'
+ message='Check mount infos failed.'
+ python3 /root/mugen-riscv/libs/locallibs/mugen_log.py --level error --message 'Check mount infos failed.'
Tue Aug 29 10:14:59 2023 - ERROR - Check mount infos failed.
+ (( exec_result++ ))
+ LOG_ERROR 'oe_test_FSIO_mount_umount_ext4.sh line 44'
+ message='oe_test_FSIO_mount_umount_ext4.sh line 44'
+ python3 /root/mugen-riscv/libs/locallibs/mugen_log.py --level error --message 'oe_test_FSIO_mount_umount_ext4.sh line 44'
Tue Aug 29 10:14:59 2023 - ERROR - oe_test_FSIO_mount_umount_ext4.sh line 44
+ return 0
+ umount /mnt/ext4_mount20230829101459
umount: /mnt/ext4_mount20230829101459: not mounted.
+ CHECK_RESULT 32 0 0 'umount ext4 failed.'
+ actual_result=32
+ expect_result=0
+ mode=0
+ error_log='umount ext4 failed.'
+ '[' -z 32 ']'
+ '[' 0 -eq 0 ']'
+ test 32x '!=' 0x
+ test -n 'umount ext4 failed.'
+ LOG_ERROR 'umount ext4 failed.'
+ message='umount ext4 failed.'
+ python3 /root/mugen-riscv/libs/locallibs/mugen_log.py --level error --message 'umount ext4 failed.'
Tue Aug 29 10:14:59 2023 - ERROR - umount ext4 failed.
+ (( exec_result++ ))
+ LOG_ERROR 'oe_test_FSIO_mount_umount_ext4.sh line 46'
+ message='oe_test_FSIO_mount_umount_ext4.sh line 46'
+ python3 /root/mugen-riscv/libs/locallibs/mugen_log.py --level error --message 'oe_test_FSIO_mount_umount_ext4.sh line 46'
Tue Aug 29 10:14:59 2023 - ERROR - oe_test_FSIO_mount_umount_ext4.sh line 46
+ return 0
+ LOG_INFO 'End to run test.'
+ message='End to run test.'
+ python3 /root/mugen-riscv/libs/locallibs/mugen_log.py --level info --message 'End to run test.'
Tue Aug 29 10:14:59 2023 - INFO  - End to run test.
+ CASE_RESULT 0
+ case_re=0
+ test -z 5
+ test 5 -gt 0
+ LOG_ERROR 'failed to execute the case.'
+ message='failed to execute the case.'
+ python3 /root/mugen-riscv/libs/locallibs/mugen_log.py --level error --message 'failed to execute the case.'
Tue Aug 29 10:14:59 2023 - ERROR - failed to execute the case.
+ exit 5
+ post_test
+ LOG_INFO 'Start to restore the test environment.'
+ message='Start to restore the test environment.'
+ python3 /root/mugen-riscv/libs/locallibs/mugen_log.py --level info --message 'Start to restore the test environment.'
Tue Aug 29 10:14:59 2023 - INFO  - Start to restore the test environment.
+ rm -rf /mnt/ext4_mount20230829101459
+ LOG_INFO 'End to restore the test environment.'
+ message='End to restore the test environment.'
+ python3 /root/mugen-riscv/libs/locallibs/mugen_log.py --level info --message 'End to restore the test environment.'
Tue Aug 29 10:14:59 2023 - INFO  - End to restore the test environment.
