+ source ../common_lib/fsio_lib.sh
++ source /root/mugen-riscv/libs/locallibs/common_lib.sh
+++ python3 --version
+++ '[' 0 -eq 0 ']'
+++ source /root/mugen-riscv/libs/locallibs/common_lib_python.sh
++ export 'FS_TYPE=ext3 ext4 xfs'
++ FS_TYPE='ext3 ext4 xfs'
++ export LANG=en_US.UTF-8
++ LANG=en_US.UTF-8
++ REMOVE_VG
++ vggroup=
++ [[ '' != '' ]]
+++ df -T
+++ grep test_vggroup
+++ awk '{print $7}'
++ mounted=
++ [[ '' != '' ]]
++ lsblk
++ grep test_vggroup
++ [[ 1 -eq 0 ]]
++ rm -rf '/tmp/point*'
+ main
++ type -t post_test
+ '[' -n function ']'
+ trap post_test EXIT INT HUP TERM
+ rpm -qa
+ grep expect
++ type -t config_params
+ '[' -n '' ']'
++ type -t pre_test
+ '[' -n function ']'
+ pre_test
+ LOG_INFO 'Start to prepare the database config.'
+ message='Start to prepare the database config.'
+ python3 /root/mugen-riscv/libs/locallibs/mugen_log.py --level info --message 'Start to prepare the database config.'
Tue Aug 29 10:14:58 2023 - INFO  - Start to prepare the database config.
++ date +%Y%m%d%H%M%S
+ cur_date=20230829101458
++ CREATE_VG
+++ date +%Y%m%d%H%M%S
++ cur_date=20230829101458
+++ lsblk
+++ grep disk
+++ awk '{print $1}'
+++ tail -n 1
++ free_disk=vda
++ disk_name=/dev/vda
++ pvcreate /dev/vda -f
++ [[ 127 -eq 0 ]]
+++ pvcreate /dev/vda
+++ grep test_vggroup
+++ cut -d '"' -f 4
++ vggroup=
++ printf
printf: usage: printf [-v var] format [arguments]
+ vggroup=
+ lv1=test_lv120230829101458
+ lv2=test_lv220230829101458
+ lv3=test_lv320230829101458
+ lvcreate -n test_lv120230829101458 -L 2G -y
oe_test_FSIO_mount_remount.sh: line 28: lvcreate: command not found
+ lvcreate -n test_lv220230829101458 -L 2G -y
oe_test_FSIO_mount_remount.sh: line 29: lvcreate: command not found
+ lvcreate -n test_lv320230829101458 -L 2G -y
oe_test_FSIO_mount_remount.sh: line 30: lvcreate: command not found
+ mkfs.ext3 /dev//test_lv120230829101458
mke2fs 1.47.0 (5-Feb-2023)
The file /dev//test_lv120230829101458 does not exist and no size was specified.
+ mkfs.ext4 /dev//test_lv220230829101458
mke2fs 1.47.0 (5-Feb-2023)
The file /dev//test_lv220230829101458 does not exist and no size was specified.
+ mkfs.xfs /dev//test_lv320230829101458
oe_test_FSIO_mount_remount.sh: line 33: mkfs.xfs: command not found
+ point=/mnt/point20230829101458
+ mkdir /mnt/point20230829101458
+ mount /dev//test_lv120230829101458 /mnt/point20230829101458
mount: /mnt/point20230829101458: special device /dev//test_lv120230829101458 does not exist.
       dmesg(1) may have more information after failed mount system call.
+ echo 'test ext3'
+ LOG_INFO 'Finish to prepare the database config.'
+ message='Finish to prepare the database config.'
+ python3 /root/mugen-riscv/libs/locallibs/mugen_log.py --level info --message 'Finish to prepare the database config.'
Tue Aug 29 10:14:58 2023 - INFO  - Finish to prepare the database config.
++ type -t run_test
+ '[' -n function ']'
+ run_test
+ LOG_INFO 'Start to run test.'
+ message='Start to run test.'
+ python3 /root/mugen-riscv/libs/locallibs/mugen_log.py --level info --message 'Start to run test.'
Tue Aug 29 10:14:58 2023 - INFO  - Start to run test.
+ mount /dev//test_lv220230829101458 /mnt/point20230829101458
mount: /mnt/point20230829101458: special device /dev//test_lv220230829101458 does not exist.
       dmesg(1) may have more information after failed mount system call.
+ CHECK_RESULT 32 0 0 'Mount ext4 on /mnt/point20230829101458 failed.'
+ actual_result=32
+ expect_result=0
+ mode=0
+ error_log='Mount ext4 on /mnt/point20230829101458 failed.'
+ '[' -z 32 ']'
+ '[' 0 -eq 0 ']'
+ test 32x '!=' 0x
+ test -n 'Mount ext4 on /mnt/point20230829101458 failed.'
+ LOG_ERROR 'Mount ext4 on /mnt/point20230829101458 failed.'
+ message='Mount ext4 on /mnt/point20230829101458 failed.'
+ python3 /root/mugen-riscv/libs/locallibs/mugen_log.py --level error --message 'Mount ext4 on /mnt/point20230829101458 failed.'
Tue Aug 29 10:14:58 2023 - ERROR - Mount ext4 on /mnt/point20230829101458 failed.
+ (( exec_result++ ))
+ LOG_ERROR 'oe_test_FSIO_mount_remount.sh line 44'
+ message='oe_test_FSIO_mount_remount.sh line 44'
+ python3 /root/mugen-riscv/libs/locallibs/mugen_log.py --level error --message 'oe_test_FSIO_mount_remount.sh line 44'
Tue Aug 29 10:14:58 2023 - ERROR - oe_test_FSIO_mount_remount.sh line 44
+ return 0
+ echo 'test ext4'
+ df -T
+ grep /mnt/point20230829101458
+ grep ext4
+ CHECK_RESULT 1 0 0 'The fs type of /mnt/point20230829101458 is not ext4.'
+ actual_result=1
+ expect_result=0
+ mode=0
+ error_log='The fs type of /mnt/point20230829101458 is not ext4.'
+ '[' -z 1 ']'
+ '[' 0 -eq 0 ']'
+ test 1x '!=' 0x
+ test -n 'The fs type of /mnt/point20230829101458 is not ext4.'
+ LOG_ERROR 'The fs type of /mnt/point20230829101458 is not ext4.'
+ message='The fs type of /mnt/point20230829101458 is not ext4.'
+ python3 /root/mugen-riscv/libs/locallibs/mugen_log.py --level error --message 'The fs type of /mnt/point20230829101458 is not ext4.'
Tue Aug 29 10:14:58 2023 - ERROR - The fs type of /mnt/point20230829101458 is not ext4.
+ (( exec_result++ ))
+ LOG_ERROR 'oe_test_FSIO_mount_remount.sh line 47'
+ message='oe_test_FSIO_mount_remount.sh line 47'
+ python3 /root/mugen-riscv/libs/locallibs/mugen_log.py --level error --message 'oe_test_FSIO_mount_remount.sh line 47'
Tue Aug 29 10:14:58 2023 - ERROR - oe_test_FSIO_mount_remount.sh line 47
+ return 0
+ mount /dev//test_lv320230829101458 /mnt/point20230829101458
mount: /mnt/point20230829101458: special device /dev//test_lv320230829101458 does not exist.
       dmesg(1) may have more information after failed mount system call.
+ CHECK_RESULT 32 0 0 'Mount xfs on /mnt/point20230829101458 failed.'
+ actual_result=32
+ expect_result=0
+ mode=0
+ error_log='Mount xfs on /mnt/point20230829101458 failed.'
+ '[' -z 32 ']'
+ '[' 0 -eq 0 ']'
+ test 32x '!=' 0x
+ test -n 'Mount xfs on /mnt/point20230829101458 failed.'
+ LOG_ERROR 'Mount xfs on /mnt/point20230829101458 failed.'
+ message='Mount xfs on /mnt/point20230829101458 failed.'
+ python3 /root/mugen-riscv/libs/locallibs/mugen_log.py --level error --message 'Mount xfs on /mnt/point20230829101458 failed.'
Tue Aug 29 10:14:58 2023 - ERROR - Mount xfs on /mnt/point20230829101458 failed.
+ (( exec_result++ ))
+ LOG_ERROR 'oe_test_FSIO_mount_remount.sh line 49'
+ message='oe_test_FSIO_mount_remount.sh line 49'
+ python3 /root/mugen-riscv/libs/locallibs/mugen_log.py --level error --message 'oe_test_FSIO_mount_remount.sh line 49'
Tue Aug 29 10:14:58 2023 - ERROR - oe_test_FSIO_mount_remount.sh line 49
+ return 0
+ echo 'test xfs'
+ df -T
+ grep /mnt/point20230829101458
+ grep xfs
+ CHECK_RESULT 1 0 0 'The fs type of /mnt/point20230829101458 is not xfs.'
+ actual_result=1
+ expect_result=0
+ mode=0
+ error_log='The fs type of /mnt/point20230829101458 is not xfs.'
+ '[' -z 1 ']'
+ '[' 0 -eq 0 ']'
+ test 1x '!=' 0x
+ test -n 'The fs type of /mnt/point20230829101458 is not xfs.'
+ LOG_ERROR 'The fs type of /mnt/point20230829101458 is not xfs.'
+ message='The fs type of /mnt/point20230829101458 is not xfs.'
+ python3 /root/mugen-riscv/libs/locallibs/mugen_log.py --level error --message 'The fs type of /mnt/point20230829101458 is not xfs.'
Tue Aug 29 10:14:58 2023 - ERROR - The fs type of /mnt/point20230829101458 is not xfs.
+ (( exec_result++ ))
+ LOG_ERROR 'oe_test_FSIO_mount_remount.sh line 52'
+ message='oe_test_FSIO_mount_remount.sh line 52'
+ python3 /root/mugen-riscv/libs/locallibs/mugen_log.py --level error --message 'oe_test_FSIO_mount_remount.sh line 52'
Tue Aug 29 10:14:58 2023 - ERROR - oe_test_FSIO_mount_remount.sh line 52
+ return 0
+ test -f /mnt/point20230829101458/testxfs
+ CHECK_RESULT 0 0 0 'The testxfs doesn'\''t exist.'
+ actual_result=0
+ expect_result=0
+ mode=0
+ error_log='The testxfs doesn'\''t exist.'
+ '[' -z 0 ']'
+ '[' 0 -eq 0 ']'
+ test 0x '!=' 0x
+ return 0
+ test -f /mnt/point20230829101458/testext4
+ CHECK_RESULT 0 1 0 'The testext4 exists unexpectly.'
+ actual_result=0
+ expect_result=1
+ mode=0
+ error_log='The testext4 exists unexpectly.'
+ '[' -z 0 ']'
+ '[' 0 -eq 0 ']'
+ test 0x '!=' 1x
+ test -n 'The testext4 exists unexpectly.'
+ LOG_ERROR 'The testext4 exists unexpectly.'
+ message='The testext4 exists unexpectly.'
+ python3 /root/mugen-riscv/libs/locallibs/mugen_log.py --level error --message 'The testext4 exists unexpectly.'
Tue Aug 29 10:14:58 2023 - ERROR - The testext4 exists unexpectly.
+ (( exec_result++ ))
+ LOG_ERROR 'oe_test_FSIO_mount_remount.sh line 56'
+ message='oe_test_FSIO_mount_remount.sh line 56'
+ python3 /root/mugen-riscv/libs/locallibs/mugen_log.py --level error --message 'oe_test_FSIO_mount_remount.sh line 56'
Tue Aug 29 10:14:58 2023 - ERROR - oe_test_FSIO_mount_remount.sh line 56
+ return 0
+ test -f /mnt/point20230829101458/testext3
+ CHECK_RESULT 0 1 0 'The testext3 exists unexpectly.'
+ actual_result=0
+ expect_result=1
+ mode=0
+ error_log='The testext3 exists unexpectly.'
+ '[' -z 0 ']'
+ '[' 0 -eq 0 ']'
+ test 0x '!=' 1x
+ test -n 'The testext3 exists unexpectly.'
+ LOG_ERROR 'The testext3 exists unexpectly.'
+ message='The testext3 exists unexpectly.'
+ python3 /root/mugen-riscv/libs/locallibs/mugen_log.py --level error --message 'The testext3 exists unexpectly.'
Tue Aug 29 10:14:58 2023 - ERROR - The testext3 exists unexpectly.
+ (( exec_result++ ))
+ LOG_ERROR 'oe_test_FSIO_mount_remount.sh line 58'
+ message='oe_test_FSIO_mount_remount.sh line 58'
+ python3 /root/mugen-riscv/libs/locallibs/mugen_log.py --level error --message 'oe_test_FSIO_mount_remount.sh line 58'
Tue Aug 29 10:14:58 2023 - ERROR - oe_test_FSIO_mount_remount.sh line 58
+ return 0
+ umount /mnt/point20230829101458
umount: /mnt/point20230829101458: not mounted.
+ df -T
+ grep /mnt/point20230829101458
+ grep ext4
+ CHECK_RESULT 1 0 0 'The fs type of /mnt/point20230829101458 is not ext4.'
+ actual_result=1
+ expect_result=0
+ mode=0
+ error_log='The fs type of /mnt/point20230829101458 is not ext4.'
+ '[' -z 1 ']'
+ '[' 0 -eq 0 ']'
+ test 1x '!=' 0x
+ test -n 'The fs type of /mnt/point20230829101458 is not ext4.'
+ LOG_ERROR 'The fs type of /mnt/point20230829101458 is not ext4.'
+ message='The fs type of /mnt/point20230829101458 is not ext4.'
+ python3 /root/mugen-riscv/libs/locallibs/mugen_log.py --level error --message 'The fs type of /mnt/point20230829101458 is not ext4.'
Tue Aug 29 10:14:58 2023 - ERROR - The fs type of /mnt/point20230829101458 is not ext4.
+ (( exec_result++ ))
+ LOG_ERROR 'oe_test_FSIO_mount_remount.sh line 61'
+ message='oe_test_FSIO_mount_remount.sh line 61'
+ python3 /root/mugen-riscv/libs/locallibs/mugen_log.py --level error --message 'oe_test_FSIO_mount_remount.sh line 61'
Tue Aug 29 10:14:58 2023 - ERROR - oe_test_FSIO_mount_remount.sh line 61
+ return 0
+ test -f /mnt/point20230829101458/testext4
+ CHECK_RESULT 0 0 0 'The testext4 doesn'\''t exist.'
+ actual_result=0
+ expect_result=0
+ mode=0
+ error_log='The testext4 doesn'\''t exist.'
+ '[' -z 0 ']'
+ '[' 0 -eq 0 ']'
+ test 0x '!=' 0x
+ return 0
+ test -f /mnt/point20230829101458/testxfs
+ CHECK_RESULT 0 1 0 'The testxfs exists unexpectly.'
+ actual_result=0
+ expect_result=1
+ mode=0
+ error_log='The testxfs exists unexpectly.'
+ '[' -z 0 ']'
+ '[' 0 -eq 0 ']'
+ test 0x '!=' 1x
+ test -n 'The testxfs exists unexpectly.'
+ LOG_ERROR 'The testxfs exists unexpectly.'
+ message='The testxfs exists unexpectly.'
+ python3 /root/mugen-riscv/libs/locallibs/mugen_log.py --level error --message 'The testxfs exists unexpectly.'
Tue Aug 29 10:14:58 2023 - ERROR - The testxfs exists unexpectly.
+ (( exec_result++ ))
+ LOG_ERROR 'oe_test_FSIO_mount_remount.sh line 65'
+ message='oe_test_FSIO_mount_remount.sh line 65'
+ python3 /root/mugen-riscv/libs/locallibs/mugen_log.py --level error --message 'oe_test_FSIO_mount_remount.sh line 65'
Tue Aug 29 10:14:58 2023 - ERROR - oe_test_FSIO_mount_remount.sh line 65
+ return 0
+ test -f /mnt/point20230829101458/testext3
+ CHECK_RESULT 0 1 0 'The testext3 exists unexpectly.'
+ actual_result=0
+ expect_result=1
+ mode=0
+ error_log='The testext3 exists unexpectly.'
+ '[' -z 0 ']'
+ '[' 0 -eq 0 ']'
+ test 0x '!=' 1x
+ test -n 'The testext3 exists unexpectly.'
+ LOG_ERROR 'The testext3 exists unexpectly.'
+ message='The testext3 exists unexpectly.'
+ python3 /root/mugen-riscv/libs/locallibs/mugen_log.py --level error --message 'The testext3 exists unexpectly.'
Tue Aug 29 10:14:58 2023 - ERROR - The testext3 exists unexpectly.
+ (( exec_result++ ))
+ LOG_ERROR 'oe_test_FSIO_mount_remount.sh line 67'
+ message='oe_test_FSIO_mount_remount.sh line 67'
+ python3 /root/mugen-riscv/libs/locallibs/mugen_log.py --level error --message 'oe_test_FSIO_mount_remount.sh line 67'
Tue Aug 29 10:14:58 2023 - ERROR - oe_test_FSIO_mount_remount.sh line 67
+ return 0
+ umount /mnt/point20230829101458
umount: /mnt/point20230829101458: not mounted.
+ df -T
+ grep /mnt/point20230829101458
+ grep ext3
+ CHECK_RESULT 1 0 0 'The fs type of /mnt/point20230829101458 is not ext3.'
+ actual_result=1
+ expect_result=0
+ mode=0
+ error_log='The fs type of /mnt/point20230829101458 is not ext3.'
+ '[' -z 1 ']'
+ '[' 0 -eq 0 ']'
+ test 1x '!=' 0x
+ test -n 'The fs type of /mnt/point20230829101458 is not ext3.'
+ LOG_ERROR 'The fs type of /mnt/point20230829101458 is not ext3.'
+ message='The fs type of /mnt/point20230829101458 is not ext3.'
+ python3 /root/mugen-riscv/libs/locallibs/mugen_log.py --level error --message 'The fs type of /mnt/point20230829101458 is not ext3.'
Tue Aug 29 10:14:58 2023 - ERROR - The fs type of /mnt/point20230829101458 is not ext3.
+ (( exec_result++ ))
+ LOG_ERROR 'oe_test_FSIO_mount_remount.sh line 70'
+ message='oe_test_FSIO_mount_remount.sh line 70'
+ python3 /root/mugen-riscv/libs/locallibs/mugen_log.py --level error --message 'oe_test_FSIO_mount_remount.sh line 70'
Tue Aug 29 10:14:58 2023 - ERROR - oe_test_FSIO_mount_remount.sh line 70
+ return 0
+ test -f /mnt/point20230829101458/testext3
+ CHECK_RESULT 0 0 0 'The testext3 doesn'\''t exist.'
+ actual_result=0
+ expect_result=0
+ mode=0
+ error_log='The testext3 doesn'\''t exist.'
+ '[' -z 0 ']'
+ '[' 0 -eq 0 ']'
+ test 0x '!=' 0x
+ return 0
+ test -f /mnt/point20230829101458/testxfs
+ CHECK_RESULT 0 1 0 'The testxfs exists unexpectly.'
+ actual_result=0
+ expect_result=1
+ mode=0
+ error_log='The testxfs exists unexpectly.'
+ '[' -z 0 ']'
+ '[' 0 -eq 0 ']'
+ test 0x '!=' 1x
+ test -n 'The testxfs exists unexpectly.'
+ LOG_ERROR 'The testxfs exists unexpectly.'
+ message='The testxfs exists unexpectly.'
+ python3 /root/mugen-riscv/libs/locallibs/mugen_log.py --level error --message 'The testxfs exists unexpectly.'
Tue Aug 29 10:14:58 2023 - ERROR - The testxfs exists unexpectly.
+ (( exec_result++ ))
+ LOG_ERROR 'oe_test_FSIO_mount_remount.sh line 74'
+ message='oe_test_FSIO_mount_remount.sh line 74'
+ python3 /root/mugen-riscv/libs/locallibs/mugen_log.py --level error --message 'oe_test_FSIO_mount_remount.sh line 74'
Tue Aug 29 10:14:58 2023 - ERROR - oe_test_FSIO_mount_remount.sh line 74
+ return 0
+ test -f /mnt/point20230829101458/testext4
+ CHECK_RESULT 0 1 0 'The testext4 exists unexpectly.'
+ actual_result=0
+ expect_result=1
+ mode=0
+ error_log='The testext4 exists unexpectly.'
+ '[' -z 0 ']'
+ '[' 0 -eq 0 ']'
+ test 0x '!=' 1x
+ test -n 'The testext4 exists unexpectly.'
+ LOG_ERROR 'The testext4 exists unexpectly.'
+ message='The testext4 exists unexpectly.'
+ python3 /root/mugen-riscv/libs/locallibs/mugen_log.py --level error --message 'The testext4 exists unexpectly.'
Tue Aug 29 10:14:58 2023 - ERROR - The testext4 exists unexpectly.
+ (( exec_result++ ))
+ LOG_ERROR 'oe_test_FSIO_mount_remount.sh line 76'
+ message='oe_test_FSIO_mount_remount.sh line 76'
+ python3 /root/mugen-riscv/libs/locallibs/mugen_log.py --level error --message 'oe_test_FSIO_mount_remount.sh line 76'
Tue Aug 29 10:14:58 2023 - ERROR - oe_test_FSIO_mount_remount.sh line 76
+ return 0
+ LOG_INFO 'End to run test.'
+ message='End to run test.'
+ python3 /root/mugen-riscv/libs/locallibs/mugen_log.py --level info --message 'End to run test.'
Tue Aug 29 10:14:59 2023 - INFO  - End to run test.
+ CASE_RESULT 0
+ case_re=0
+ test -z 12
+ test 12 -gt 0
+ LOG_ERROR 'failed to execute the case.'
+ message='failed to execute the case.'
+ python3 /root/mugen-riscv/libs/locallibs/mugen_log.py --level error --message 'failed to execute the case.'
Tue Aug 29 10:14:59 2023 - ERROR - failed to execute the case.
+ exit 12
+ post_test
+ LOG_INFO 'Start to restore the test environment.'
+ message='Start to restore the test environment.'
+ python3 /root/mugen-riscv/libs/locallibs/mugen_log.py --level info --message 'Start to restore the test environment.'
Tue Aug 29 10:14:59 2023 - INFO  - Start to restore the test environment.
+ umount /mnt/point20230829101458
umount: /mnt/point20230829101458: not mounted.
+ rm -rf /mnt/point20230829101458
+ LOG_INFO 'End to restore the test environment.'
+ message='End to restore the test environment.'
+ python3 /root/mugen-riscv/libs/locallibs/mugen_log.py --level info --message 'End to restore the test environment.'
Tue Aug 29 10:14:59 2023 - INFO  - End to restore the test environment.
