+ source ../common_lib/fsio_lib.sh
++ source /root/mugen-riscv/libs/locallibs/common_lib.sh
+++ python3 --version
+++ '[' 0 -eq 0 ']'
+++ source /root/mugen-riscv/libs/locallibs/common_lib_python.sh
++ export 'FS_TYPE=ext3 ext4 xfs'
++ FS_TYPE='ext3 ext4 xfs'
++ export LANG=en_US.UTF-8
++ LANG=en_US.UTF-8
++ REMOVE_VG
++ vggroup=
++ [[ '' != '' ]]
+++ df -T
+++ grep test_vggroup
+++ awk '{print $7}'
++ mounted=
++ [[ '' != '' ]]
++ lsblk
++ grep test_vggroup
++ [[ 1 -eq 0 ]]
++ rm -rf /tmp/point120230901153756
+ main
++ type -t post_test
+ '[' -n function ']'
+ trap post_test EXIT INT HUP TERM
+ rpm -qa
+ grep expect
++ type -t config_params
+ '[' -n '' ']'
++ type -t pre_test
+ '[' -n function ']'
+ pre_test
+ LOG_INFO 'Start to prepare the database config.'
+ message='Start to prepare the database config.'
+ python3 /root/mugen-riscv/libs/locallibs/mugen_log.py --level info --message 'Start to prepare the database config.'
Fri Sep  1 15:38:13 2023 - INFO  - Start to prepare the database config.
++ date +%Y%m%d%H%M%S
+ cur_date=20230901153813
++ CREATE_VG
+++ date +%Y%m%d%H%M%S
++ cur_date=20230901153813
+++ lsblk
+++ grep disk
+++ awk '{print $1}'
+++ tail -n 1
++ free_disk=vda
++ disk_name=/dev/vda
++ pvcreate /dev/vda -f
++ [[ 5 -eq 0 ]]
+++ pvcreate /dev/vda
+++ grep test_vggroup
+++ cut -d '"' -f 4
++ vggroup=
++ printf
printf: usage: printf [-v var] format [arguments]
+ vggroup=
+ lv=test_lv20230901153813
+ lvcreate -n test_lv20230901153813 -L 2G -y
  No command with matching syntax recognised.  Run 'lvcreate --help' for more information.
  Nearest similar command has syntax:
+ mkfs.ext3 /dev//test_lv20230901153813
mke2fs 1.47.0 (5-Feb-2023)
The file /dev//test_lv20230901153813 does not exist and no size was specified.
+ ext3_point=/mnt/test20230901153813
+ mkdir /mnt/test20230901153813
+ data=('remount-ro' 'continue' 'panic')
+ LOG_INFO 'Finish to prepare the database config.'
+ message='Finish to prepare the database config.'
+ python3 /root/mugen-riscv/libs/locallibs/mugen_log.py --level info --message 'Finish to prepare the database config.'
Fri Sep  1 15:38:14 2023 - INFO  - Finish to prepare the database config.
++ type -t run_test
+ '[' -n function ']'
+ run_test
+ LOG_INFO 'Start to run test.'
+ message='Start to run test.'
+ python3 /root/mugen-riscv/libs/locallibs/mugen_log.py --level info --message 'Start to run test.'
Fri Sep  1 15:38:14 2023 - INFO  - Start to run test.
+ for var in ${data[@]}
+ mount -t ext3 -o errors=remount-ro /dev//test_lv20230901153813 /mnt/test20230901153813
mount: /mnt/test20230901153813: special device /dev//test_lv20230901153813 does not exist.
       dmesg(1) may have more information after failed mount system call.
+ CHECK_RESULT 32 0 0 'Mount ext3 by errors=remount-ro failed.'
+ actual_result=32
+ expect_result=0
+ mode=0
+ error_log='Mount ext3 by errors=remount-ro failed.'
+ '[' -z 32 ']'
+ '[' 0 -eq 0 ']'
+ test 32x '!=' 0x
+ test -n 'Mount ext3 by errors=remount-ro failed.'
+ LOG_ERROR 'Mount ext3 by errors=remount-ro failed.'
+ message='Mount ext3 by errors=remount-ro failed.'
+ python3 /root/mugen-riscv/libs/locallibs/mugen_log.py --level error --message 'Mount ext3 by errors=remount-ro failed.'
Fri Sep  1 15:38:15 2023 - ERROR - Mount ext3 by errors=remount-ro failed.
+ (( exec_result++ ))
+ LOG_ERROR 'oe_test_FSIO_mount_ext3_setErrors.sh line 38'
+ message='oe_test_FSIO_mount_ext3_setErrors.sh line 38'
+ python3 /root/mugen-riscv/libs/locallibs/mugen_log.py --level error --message 'oe_test_FSIO_mount_ext3_setErrors.sh line 38'
Fri Sep  1 15:38:15 2023 - ERROR - oe_test_FSIO_mount_ext3_setErrors.sh line 38
+ return 0
+ umount -f /dev//test_lv20230901153813
umount: /dev//test_lv20230901153813: no mount point specified.
+ for var in ${data[@]}
+ mount -t ext3 -o errors=continue /dev//test_lv20230901153813 /mnt/test20230901153813
mount: /mnt/test20230901153813: special device /dev//test_lv20230901153813 does not exist.
       dmesg(1) may have more information after failed mount system call.
+ CHECK_RESULT 32 0 0 'Mount ext3 by errors=continue failed.'
+ actual_result=32
+ expect_result=0
+ mode=0
+ error_log='Mount ext3 by errors=continue failed.'
+ '[' -z 32 ']'
+ '[' 0 -eq 0 ']'
+ test 32x '!=' 0x
+ test -n 'Mount ext3 by errors=continue failed.'
+ LOG_ERROR 'Mount ext3 by errors=continue failed.'
+ message='Mount ext3 by errors=continue failed.'
+ python3 /root/mugen-riscv/libs/locallibs/mugen_log.py --level error --message 'Mount ext3 by errors=continue failed.'
Fri Sep  1 15:38:15 2023 - ERROR - Mount ext3 by errors=continue failed.
+ (( exec_result++ ))
+ LOG_ERROR 'oe_test_FSIO_mount_ext3_setErrors.sh line 38'
+ message='oe_test_FSIO_mount_ext3_setErrors.sh line 38'
+ python3 /root/mugen-riscv/libs/locallibs/mugen_log.py --level error --message 'oe_test_FSIO_mount_ext3_setErrors.sh line 38'
Fri Sep  1 15:38:16 2023 - ERROR - oe_test_FSIO_mount_ext3_setErrors.sh line 38
+ return 0
+ umount -f /dev//test_lv20230901153813
umount: /dev//test_lv20230901153813: no mount point specified.
+ for var in ${data[@]}
+ mount -t ext3 -o errors=panic /dev//test_lv20230901153813 /mnt/test20230901153813
mount: /mnt/test20230901153813: special device /dev//test_lv20230901153813 does not exist.
       dmesg(1) may have more information after failed mount system call.
+ CHECK_RESULT 32 0 0 'Mount ext3 by errors=panic failed.'
+ actual_result=32
+ expect_result=0
+ mode=0
+ error_log='Mount ext3 by errors=panic failed.'
+ '[' -z 32 ']'
+ '[' 0 -eq 0 ']'
+ test 32x '!=' 0x
+ test -n 'Mount ext3 by errors=panic failed.'
+ LOG_ERROR 'Mount ext3 by errors=panic failed.'
+ message='Mount ext3 by errors=panic failed.'
+ python3 /root/mugen-riscv/libs/locallibs/mugen_log.py --level error --message 'Mount ext3 by errors=panic failed.'
Fri Sep  1 15:38:16 2023 - ERROR - Mount ext3 by errors=panic failed.
+ (( exec_result++ ))
+ LOG_ERROR 'oe_test_FSIO_mount_ext3_setErrors.sh line 38'
+ message='oe_test_FSIO_mount_ext3_setErrors.sh line 38'
+ python3 /root/mugen-riscv/libs/locallibs/mugen_log.py --level error --message 'oe_test_FSIO_mount_ext3_setErrors.sh line 38'
Fri Sep  1 15:38:17 2023 - ERROR - oe_test_FSIO_mount_ext3_setErrors.sh line 38
+ return 0
+ umount -f /dev//test_lv20230901153813
umount: /dev//test_lv20230901153813: no mount point specified.
+ LOG_INFO 'End to run test.'
+ message='End to run test.'
+ python3 /root/mugen-riscv/libs/locallibs/mugen_log.py --level info --message 'End to run test.'
Fri Sep  1 15:38:17 2023 - INFO  - End to run test.
+ CASE_RESULT 0
+ case_re=0
+ test -z 3
+ test 3 -gt 0
+ LOG_ERROR 'failed to execute the case.'
+ message='failed to execute the case.'
+ python3 /root/mugen-riscv/libs/locallibs/mugen_log.py --level error --message 'failed to execute the case.'
Fri Sep  1 15:38:18 2023 - ERROR - failed to execute the case.
+ exit 3
+ post_test
+ LOG_INFO 'Start to restore the test environment.'
+ message='Start to restore the test environment.'
+ python3 /root/mugen-riscv/libs/locallibs/mugen_log.py --level info --message 'Start to restore the test environment.'
Fri Sep  1 15:38:18 2023 - INFO  - Start to restore the test environment.
+ rm -rf /mnt/test20230901153813
+ LOG_INFO 'End to restore the test environment.'
+ message='End to restore the test environment.'
+ python3 /root/mugen-riscv/libs/locallibs/mugen_log.py --level info --message 'End to restore the test environment.'
Fri Sep  1 15:38:18 2023 - INFO  - End to restore the test environment.
